#usda 1.0
(
    customLayerData = {
        string creator = "URDF USD Converter v0.1.3"
    }
    defaultPrim = "reBot_B601_DM"
    doc = """Generated from Composed Stage of root layer /tmp/tmp8pcvqz0_/reBot_B601_DM.usdc


Generated from Composed Stage of root layer /tmp/urdf_import_reBot_B601_DM_k19dm8r1/usdex_reBot_B601_DM/reBot_B601_DM.usdc


Generated from Composed Stage of root layer /tmp/urdf_import_reBot_B601_DM_k19dm8r1/temp_reBot_B601_DM/reBot_B601_DM.usd


Generated from Composed Stage of root layer /home/welt/repo/reBot-Isaacsim/urdf/reBot_B601_DM/urdf/reBot_B601_DM/payloads/base.usd
"""
    kilogramsPerUnit = 1
    metersPerUnit = 1
    upAxis = "Z"
)

over "reBot_B601_DM"
{
    over "Geometry"
    {
        over "base_link" (
            prepend apiSchemas = ["PhysicsRigidBodyAPI", "PhysicsArticulationRootAPI", "NewtonArticulationRootAPI", "PhysicsMassAPI"]
        )
        {
            bool newton:selfCollisionEnabled = 0
            point3f physics:centerOfMass = (-0.0000027052313, -0.000007701343, 0.028980834)
            float3 physics:diagonalInertia = (0.0010041303, 0.0016792293, 0.0024399206)
            float physics:mass = 0.7987448
            quatf physics:principalAxes = (0.00006290141, 0.7071078, 0.7071058, 0.000044576023)

            over "link1" (
                prepend apiSchemas = ["PhysicsRigidBodyAPI", "PhysicsMassAPI"]
            )
            {
                point3f physics:centerOfMass = (0.000012058491, -0.0005224627, 0.01977218)
                float3 physics:diagonalInertia = (0.000050888597, 0.00007432795, 0.00009145189)
                float physics:mass = 0.08407365
                quatf physics:principalAxes = (-0.31826365, 0.6314347, 0.63143075, 0.3182667)

                over "link2" (
                    prepend apiSchemas = ["PhysicsRigidBodyAPI", "PhysicsMassAPI"]
                )
                {
                    point3f physics:centerOfMass = (-0.13224463, -0.003050316, -0.03092994)
                    float3 physics:diagonalInertia = (0.00025002495, 0.0018600177, 0.0018632809)
                    float physics:mass = 0.7103944
                    quatf physics:principalAxes = (0.753329, -0.6576436, -0.0003269026, -0.00037585833)

                    over "link3" (
                        prepend apiSchemas = ["PhysicsRigidBodyAPI", "PhysicsMassAPI"]
                    )
                    {
                        point3f physics:centerOfMass = (0.12150751, -0.05375681, -0.031086178)
                        float3 physics:diagonalInertia = (0.00015990717, 0.0012492861, 0.0012557008)
                        float physics:mass = 0.5249416
                        quatf physics:principalAxes = (0.9997847, -0.019319411, -0.0013781198, 0.007446615)

                        over "link4" (
                            prepend apiSchemas = ["PhysicsRigidBodyAPI", "PhysicsMassAPI"]
                        )
                        {
                            point3f physics:centerOfMass = (0.061238185, -0.05152295, -0.030334035)
                            float3 physics:diagonalInertia = (0.0000689486, 0.00010113906, 0.000115772345)
                            float physics:mass = 0.1911392
                            quatf physics:principalAxes = (0.7062643, -0.69686615, 0.08645443, 0.089966215)

                            over "link5" (
                                prepend apiSchemas = ["PhysicsRigidBodyAPI", "PhysicsMassAPI"]
                            )
                            {
                                point3f physics:centerOfMass = (-0.0050493306, 0.0000017460303, 0.03878663)
                                float3 physics:diagonalInertia = (0.000051718653, 0.000053800297, 0.0000684851)
                                float physics:mass = 0.1500041
                                quatf physics:principalAxes = (-0.5455848, 0.449344, 0.44718722, 0.5481339)

                                over "link6" (
                                    prepend apiSchemas = ["PhysicsRigidBodyAPI", "PhysicsMassAPI"]
                                )
                                {
                                    point3f physics:centerOfMass = (-0.000017603443, 7.6144975e-9, 0.0043172254)
                                    float3 physics:diagonalInertia = (0.0000043771274, 0.000004428012, 0.000008552497)
                                    float physics:mass = 0.018727167
                                    quatf physics:principalAxes = (0.000013011839, 0.70710766, 0.7071059, -0.0000130557455)

                                    over "gripper_link" (
                                        prepend apiSchemas = ["PhysicsRigidBodyAPI", "PhysicsMassAPI"]
                                    )
                                    {
                                        point3f physics:centerOfMass = (-0.11400456, 0.00007308093, -8.0982375e-8)
                                        float3 physics:diagonalInertia = (0.000058508143, 0.00020521354, 0.00023238627)
                                        float physics:mass = 0.18180016
                                        quatf physics:principalAxes = (-0.49962616, 0.49957532, 0.5004129, 0.50038505)

                                        over "gripper_left" (
                                            prepend apiSchemas = ["PhysicsRigidBodyAPI", "PhysicsMassAPI"]
                                        )
                                        {
                                            point3f physics:centerOfMass = (0.009371546, -0.018351441, -0.0021305082)
                                            float3 physics:diagonalInertia = (0.000008556453, 0.000010831226, 0.000011383922)
                                            float physics:mass = 0.042327896
                                            quatf physics:principalAxes = (0.9206009, -0.0891947, 0.022860859, 0.37949392)
                                        }

                                        over "gripper_right" (
                                            prepend apiSchemas = ["PhysicsRigidBodyAPI", "PhysicsMassAPI"]
                                        )
                                        {
                                            point3f physics:centerOfMass = (0.009371546, 0.018351441, 0.0021305082)
                                            float3 physics:diagonalInertia = (0.000008556453, 0.000010831226, 0.000011383922)
                                            float physics:mass = 0.042327896
                                            quatf physics:principalAxes = (0.9206009, -0.08919468, -0.022860846, -0.37949395)
                                        }
                                    }
                                }
                            }
                        }
                    }
                }
            }
        }
    }

    over "Physics"
    {
        def PhysicsRevoluteJoint "joint1" (
            prepend apiSchemas = ["PhysicsDriveAPI:angular", "PhysicsJointStateAPI:angular"]
        )
        {
            float drive:angular:physics:maxForce = 27
            uniform token physics:axis = "Z"
            custom rel physics:body0
            prepend rel physics:body0 = </reBot_B601_DM/Geometry/base_link>
            custom rel physics:body1
            prepend rel physics:body1 = </reBot_B601_DM/Geometry/base_link/link1>
            point3f physics:localPos0 = (-0.00008416, 0, 0.08465)
            point3f physics:localPos1 = (0, 0, 0)
            quatf physics:localRot0 = (1, 0, 0, 0)
            quatf physics:localRot1 = (1, 0, 0, 0)
            float physics:lowerLimit = -160.42818
            float physics:upperLimit = 160.42818
            custom float urdf:limit:effort = 27
            custom float urdf:limit:velocity = 50
        }

        def PhysicsRevoluteJoint "joint2" (
            prepend apiSchemas = ["PhysicsDriveAPI:angular", "PhysicsJointStateAPI:angular"]
        )
        {
            float drive:angular:physics:maxForce = 27
            uniform token physics:axis = "Z"
            custom rel physics:body0
            prepend rel physics:body0 = </reBot_B601_DM/Geometry/base_link/link1>
            custom rel physics:body1
            prepend rel physics:body1 = </reBot_B601_DM/Geometry/base_link/link1/link2>
            point3f physics:localPos0 = (0.020084, 0.031625, 0.05555)
            point3f physics:localPos1 = (0, 0, 0)
            quatf physics:localRot0 = (0.7071081, 0.70710546, 0, 0)
            quatf physics:localRot1 = (0, -1, 0, 0)
            float physics:lowerLimit = -179.90875
            float physics:upperLimit = 0
            custom float urdf:limit:effort = 27
            custom float urdf:limit:velocity = 50
        }

        def PhysicsRevoluteJoint "joint3" (
            prepend apiSchemas = ["PhysicsDriveAPI:angular", "PhysicsJointStateAPI:angular"]
        )
        {
            float drive:angular:physics:maxForce = 27
            uniform token physics:axis = "Z"
            custom rel physics:body0
            prepend rel physics:body0 = </reBot_B601_DM/Geometry/base_link/link1/link2>
            custom rel physics:body1
            prepend rel physics:body1 = </reBot_B601_DM/Geometry/base_link/link1/link2/link3>
            point3f physics:localPos0 = (-0.264, 0, 0)
            point3f physics:localPos1 = (0, 0, 0)
            quatf physics:localRot0 = (1, 0, 0, 0)
            quatf physics:localRot1 = (1, 0, 0, 0)
            float physics:lowerLimit = -179.90875
            float physics:upperLimit = 0
            custom float urdf:limit:effort = 27
            custom float urdf:limit:velocity = 50
        }

        def PhysicsRevoluteJoint "joint4" (
            prepend apiSchemas = ["PhysicsDriveAPI:angular", "PhysicsJointStateAPI:angular"]
        )
        {
            float drive:angular:physics:maxForce = 7
            uniform token physics:axis = "Z"
            custom rel physics:body0
            prepend rel physics:body0 = </reBot_B601_DM/Geometry/base_link/link1/link2/link3>
            custom rel physics:body1
            prepend rel physics:body1 = </reBot_B601_DM/Geometry/base_link/link1/link2/link3/link4>
            point3f physics:localPos0 = (0.2426, -0.054, -0.001625)
            point3f physics:localPos1 = (0, 0, 0)
            quatf physics:localRot0 = (1, 0, 0, 0)
            quatf physics:localRot1 = (1, 0, 0, 0)
            float physics:lowerLimit = -107.143105
            float physics:upperLimit = 89.95438
            custom float urdf:limit:effort = 7
            custom float urdf:limit:velocity = 200
        }

        def PhysicsRevoluteJoint "joint5" (
            prepend apiSchemas = ["PhysicsDriveAPI:angular", "PhysicsJointStateAPI:angular"]
        )
        {
            float drive:angular:physics:maxForce = 7
            uniform token physics:axis = "Z"
            custom rel physics:body0
            prepend rel physics:body0 = </reBot_B601_DM/Geometry/base_link/link1/link2/link3/link4>
            custom rel physics:body1
            prepend rel physics:body1 = </reBot_B601_DM/Geometry/base_link/link1/link2/link3/link4/link5>
            point3f physics:localPos0 = (0.078308, -0.0375, -0.03)
            point3f physics:localPos1 = (0, 0, 0)
            quatf physics:localRot0 = (0.70710546, -0.7071081, 0, 0)
            quatf physics:localRot1 = (1, 0, 0, 0)
            float physics:lowerLimit = -89.95438
            float physics:upperLimit = 89.95438
            custom float urdf:limit:effort = 7
            custom float urdf:limit:velocity = 200
        }

        def PhysicsRevoluteJoint "joint6" (
            prepend apiSchemas = ["PhysicsDriveAPI:angular", "PhysicsJointStateAPI:angular"]
        )
        {
            float drive:angular:physics:maxForce = 7
            uniform token physics:axis = "Z"
            custom rel physics:body0
            prepend rel physics:body0 = </reBot_B601_DM/Geometry/base_link/link1/link2/link3/link4/link5>
            custom rel physics:body1
            prepend rel physics:body1 = </reBot_B601_DM/Geometry/base_link/link1/link2/link3/link4/link5/link6>
            point3f physics:localPos0 = (0.023692, 0, 0.04)
            point3f physics:localPos1 = (0, 0, 0)
            quatf physics:localRot0 = (0.70710546, -3.3148634e-17, 0.7071081, 3.7116984e-17)
            quatf physics:localRot1 = (1, 0, 0, 0)
            float physics:lowerLimit = -179.90875
            float physics:upperLimit = 179.90875
            custom float urdf:limit:effort = 7
            custom float urdf:limit:velocity = 200
        }

        def PhysicsPrismaticJoint "gripper_joint1" (
            prepend apiSchemas = ["PhysicsDriveAPI:linear", "PhysicsJointStateAPI:linear"]
        )
        {
            float drive:linear:physics:maxForce = 100
            uniform token physics:axis = "X"
            custom rel physics:body0
            prepend rel physics:body0 = </reBot_B601_DM/Geometry/base_link/link1/link2/link3/link4/link5/link6/gripper_link>
            custom rel physics:body1
            prepend rel physics:body1 = </reBot_B601_DM/Geometry/base_link/link1/link2/link3/link4/link5/link6/gripper_link/gripper_left>
            point3f physics:localPos0 = (-0.042091, 0.000027531, -0.000013031)
            point3f physics:localPos1 = (0, 0, 0)
            quatf physics:localRot0 = (-0.70710546, 2.8129923e-10, 4.6353518e-10, 0.7071081)
            quatf physics:localRot1 = (1, 0, 0, 0)
            float physics:lowerLimit = 0
            float physics:upperLimit = 0.0715
            custom float urdf:limit:effort = 100
            custom float urdf:limit:velocity = 15
        }

        def PhysicsPrismaticJoint "gripper_joint2" (
            prepend apiSchemas = ["PhysicsDriveAPI:linear", "PhysicsJointStateAPI:linear"]
        )
        {
            float drive:linear:physics:maxForce = 100
            uniform token physics:axis = "X"
            custom rel physics:body0
            prepend rel physics:body0 = </reBot_B601_DM/Geometry/base_link/link1/link2/link3/link4/link5/link6/gripper_link>
            custom rel physics:body1
            prepend rel physics:body1 = </reBot_B601_DM/Geometry/base_link/link1/link2/link3/link4/link5/link6/gripper_link/gripper_right>
            point3f physics:localPos0 = (-0.042091, -0.000027531, 0.000013031)
            point3f physics:localPos1 = (0, 0, 0)
            quatf physics:localRot0 = (0.70710546, -4.635341e-10, 2.8130093e-10, 0.7071081)
            quatf physics:localRot1 = (1, 0, 0, 0)
            float physics:lowerLimit = 0
            float physics:upperLimit = 0.0715
            custom float urdf:limit:effort = 100
            custom float urdf:limit:velocity = 15
        }

        def PhysicsFixedJoint "root_joint"
        {
            custom rel physics:body0
            prepend rel physics:body0 = </reBot_B601_DM>
            custom rel physics:body1
            prepend rel physics:body1 = </reBot_B601_DM/Geometry/base_link>
            point3f physics:localPos0 = (0, 0, 0)
            point3f physics:localPos1 = (0, 0, 0)
            quatf physics:localRot0 = (1, 0, 0, 0)
            quatf physics:localRot1 = (1, 0, 0, 0)
        }

        def PhysicsFixedJoint "gripper_joint"
        {
            custom rel physics:body0
            prepend rel physics:body0 = </reBot_B601_DM/Geometry/base_link/link1/link2/link3/link4/link5/link6>
            custom rel physics:body1
            prepend rel physics:body1 = </reBot_B601_DM/Geometry/base_link/link1/link2/link3/link4/link5/link6/gripper_link>
            point3f physics:localPos0 = (2.7755576e-17, 0, 0.15971)
            point3f physics:localPos1 = (0, 0, 0)
            quatf physics:localRot0 = (0.0000025977158, -0.70710546, -0.0000025977254, -0.7071081)
            quatf physics:localRot1 = (1, 0, 0, 0)
        }
    }
}

